Workbook

Sheet Summary
A1: Berkeley FY2027 Special-Tax & Bond Burden — Verification Worksheet
A2: Example parcel: 1,800 sq ft dwelling, assessed value $1,250,000. Compiled by Berkeley Transparency Hub (BeTH). Prepared 2026-06-15.
A3: STATUS: FY2027 rate ordinances ADOPTED 6/30/26 (2nd reading). All 13 figures MATCH the published estimates exactly. Figures now official.
A5: Assumptions
A6: Dwelling size (sq ft) | B6: 1800
A7: Assessed value ($) | B7: 1250000
A9: Headline Totals (this parcel)
A10: Per-square-foot parcel taxes | B10: ='Line Items'!F20 -> 2001.006 | C10: Items 3,4,8,9,10,11,13,15
A11: Ad valorem bond levies | B11: ='Line Items'!F21 -> 612.5 | C11: Items 6,7,12,14,16
A12: COMBINED ANNUAL | B12: ='Line Items'!F22 -> 2613.506 | C12: All items 3–16
A13: Combined monthly | B13: ='Line Items'!F22/12 -> 217.79217
A16: Read before publishing
A17: 1. NOT NEW TAXES. Items 3–16 are the annual rate-SETTING for taxes Berkeley voters already approved. This is the existing special-tax stack, not new burden created by a single vote. Label accordingly.
A18: 2. BOND LINES VARY BY HOME VALUE. The ad valorem bonds (Items 6,7,12,14,16) scale with ASSESSED value (Prop 13 basis), not size. A long-held home pays far less; a recent purchase far more. The ~$600 bond figure is specific to a $1.25M assessment. The ~$2,000 sq-ft portion does NOT vary with value.
A19: 4. RATES NOW OFFICIAL. All FY2027 special-tax & bond rates adopted by ordinance on June 30, 2026; every figure matches the prior estimate to the digit.
A20: 4. RATES ARE ESTIMATES UNTIL ADOPTED. Verified items track FY2026 actuals + escalator. The 5 ad valorem bond rates are debt-service-driven (not escalator-driven) and should NOT be published until the ordinance posts.

Sheet Line Items
A1: FY2027 Line-Item Verification
A2: Geoff's figures vs official FY2026 rates. 'sqft' basis = ¢/sq ft × 1,800; 'av' basis = % × $1,250,000.
A4: Item | B4: Measure / Description | C4: Basis | D4: Geoff FY27 (as published) | E4: Rate (num) | F4: Geoff annual cost | G4: Official FY2026 rate | H4: FY26 (num) | I4: FY26-basis cost | J4: Implied YoY | K4: Status | L4: Source / Notes | M4: Adopted FY27 rate (Ord., 6/30/26)
A5: 3 | B5: Library Relief Act of 2024 (Measure X) | C5: sqft | D5: 6.297¢ / sq ft | E5: 0.06297 | F5: =IF(C5="sqft",E5*Summary!$B$6,E5*Summary!$B$7) -> 113.346 | G5: 6.0¢ (eff 7/1/25) | H5: 0.06 | I5: =IF(H5="","",IF(C5="sqft",H5*Summary!$B$6,H5*Summary!$B$7)) -> 108 | J5: =IF(H5="","",(E5-H5)/H5) -> 0.0495 | K5: ADOPTED — MATCHES estimate ✓ | L5: BMC 7.57.020; new additive library tax | M5: Ord 8,013: 6.297¢/sf dwell; 9.446¢ comm
A6: 4 | B6: Library Services Tax (1980 Act) | C6: sqft | D6: 31.28¢ / sq ft | E6: 0.3128 | F6: =IF(C6="sqft",E6*Summary!$B$6,E6*Summary!$B$7) -> 563.04 | G6: ~29.80¢ (FY26) | H6: 0.298 | I6: =IF(H6="","",IF(C6="sqft",H6*Summary!$B$6,H6*Summary!$B$7)) -> 536.4 | J6: =IF(H6="","",(E6-H6)/H6) -> 0.04966443 | K6: ADOPTED — MATCHES estimate ✓ | L6: FY26 library rate; BMC 7.56.020 | M6: Ord 8,014: 31.28¢/sf dwell; 47.29¢ comm
A7: 6 | B7: Debt service, 2015 Refunding Bonds (G/S/I) | C7: av | D7: 0.0075% of AV | E7: 7.5e-05 | F7: =IF(C7="sqft",E7*Summary!$B$6,E7*Summary!$B$7) -> 93.75 | G7: — | I7: =IF(H7="","",IF(C7="sqft",H7*Summary!$B$6,H7*Summary!$B$7)) | J7: =IF(H7="","",(E7-H7)/H7) | K7: ADOPTED — MATCHES estimate ✓ | L7: Ad valorem; debt-service driven, not escalator | M7: Ord 8,016: 0.0075% AV
A8: 7 | B8: Affordable Housing Bonds (Measure O) | C8: av | D8: 0.0200% of AV | E8: 0.0002 | F8: =IF(C8="sqft",E8*Summary!$B$6,E8*Summary!$B$7) -> 250 | G8: — | I8: =IF(H8="","",IF(C8="sqft",H8*Summary!$B$6,H8*Summary!$B$7)) | J8: =IF(H8="","",(E8-H8)/H8) | K8: ADOPTED — MATCHES estimate ✓ | L8: Ad valorem; debt-service driven | M8: Ord 8,017: 0.0200% AV
A9: 8 | B9: Emergency Services for the Disabled (Measure E) | C9: sqft | D9: 2.339¢ / sq ft | E9: 0.02339 | F9: =IF(C9="sqft",E9*Summary!$B$6,E9*Summary!$B$7) -> 42.102 | G9: — | I9: =IF(H9="","",IF(C9="sqft",H9*Summary!$B$6,H9*Summary!$B$7)) | J9: =IF(H9="","",(E9-H9)/H9) | K9: ADOPTED — MATCHES estimate ✓ | L9: Plausible; not independently confirmed | M9: Ord 8,018: 2.339¢/sf
A10: 9 | B10: Fire Protection & Emergency Prep (Measure GG) | C10: sqft | D10: 7.026¢ / sq ft | E10: 0.07026 | F10: =IF(C10="sqft",E10*Summary!$B$6,E10*Summary!$B$7) -> 126.468 | G10: 6.695¢ (FY26 ord.) | H10: 0.06695 | I10: =IF(H10="","",IF(C10="sqft",H10*Summary!$B$6,H10*Summary!$B$7)) -> 120.51 | J10: =IF(H10="","",(E10-H10)/H10) -> 0.049439881 | K10: ADOPTED — MATCHES estimate ✓ | L10: Ord. 6/24/25; dwelling rate | M10: Ord 8,019: 7.026¢/sf dwell; 10.634¢ other
A11: 10 | B11: Firefighting, EMS & Wildfire (Measure FF 2020) | C11: sqft | D11: 13.633¢ / sq ft | E11: 0.13633 | F11: =IF(C11="sqft",E11*Summary!$B$6,E11*Summary!$B$7) -> 245.394 | G11: — | I11: =IF(H11="","",IF(C11="sqft",H11*Summary!$B$6,H11*Summary!$B$7)) | J11: =IF(H11="","",(E11-H11)/H11) | K11: ADOPTED — MATCHES estimate ✓ | L11: 2020 base $0.1047; escalated value plausible | M11: Ord 8,020: 13.633¢/sf
A12: 11 | B12: Emergency Medical Services (Paramedic Tax) | C12: sqft | D12: 4.92¢ / sq ft | E12: 0.0492 | F12: =IF(C12="sqft",E12*Summary!$B$6,E12*Summary!$B$7) -> 88.56 | G12: 4.74¢ (FY26 ord.) | H12: 0.0474 | I12: =IF(H12="","",IF(C12="sqft",H12*Summary!$B$6,H12*Summary!$B$7)) -> 85.32 | J12: =IF(H12="","",(E12-H12)/H12) -> 0.037974684 | K12: ADOPTED — MATCHES estimate ✓ | L12: Ord. 6/17/25 | M12: Ord 8,021: 4.92¢/sf
A13: 12 | B13: Infrastructure & Facilities Bonds (Measure T1) | C13: av | D13: 0.0140% of AV | E13: 0.00014 | F13: =IF(C13="sqft",E13*Summary!$B$6,E13*Summary!$B$7) -> 175 | G13: — | I13: =IF(H13="","",IF(C13="sqft",H13*Summary!$B$6,H13*Summary!$B$7)) | J13: =IF(H13="","",(E13-H13)/H13) | K13: ADOPTED — MATCHES estimate ✓ | L13: Ad valorem; debt-service driven | M13: Ord 8,022: 0.0140% AV
A14: 13 | B14: Parks, Trees & Landscaping Tax (Measures F & Y) | C14: sqft | D14: 27.83¢ / sq ft | E14: 0.2783 | F14: =IF(C14="sqft",E14*Summary!$B$6,E14*Summary!$B$7) -> 500.94 | G14: 26.52¢ (Measure Y, FY26) | H14: 0.2652 | I14: =IF(H14="","",IF(C14="sqft",H14*Summary!$B$6,H14*Summary!$B$7)) -> 477.36 | J14: =IF(H14="","",(E14-H14)/H14) -> 0.049396682 | K14: ADOPTED — MATCHES estimate ✓ | L14: Measure Y (2024) raised to $0.2652/sf | M14: Ord 8,023: 27.83¢/sf
A15: 14 | B15: Branch Library Bonds (2008 Measure FF) | C15: av | D15: 0.0035% of AV | E15: 3.5e-05 | F15: =IF(C15="sqft",E15*Summary!$B$6,E15*Summary!$B$7) -> 43.75 | G15: 0.0040% (FY26 ord.) | H15: 4e-05 | I15: =IF(H15="","",IF(C15="sqft",H15*Summary!$B$6,H15*Summary!$B$7)) -> 50 | J15: =IF(H15="","",(E15-H15)/H15) -> -0.125 | K15: ADOPTED — MATCHES estimate ✓ | L15: Ord. 6/17/25; bond rate falls as debt paid | M15: Ord 8,024: 0.0035% AV
A16: 15 | B16: Safe Streets Tax (2024 Measure FF) | C16: sqft | D16: 17.842¢ / sq ft | E16: 0.17842 | F16: =IF(C16="sqft",E16*Summary!$B$6,E16*Summary!$B$7) -> 321.156 | G16: 17.0¢ (FY26) | H16: 0.17 | I16: =IF(H16="","",IF(C16="sqft",H16*Summary!$B$6,H16*Summary!$B$7)) -> 306 | J16: =IF(H16="","",(E16-H16)/H16) -> 0.049529412 | K16: ADOPTED — MATCHES estimate ✓ | L16: FY26 street/sidewalk rate | M16: Ord 8,025: 17.842¢/sf dwell; 26.238¢ comm
A17: 16 | B17: Street & Watershed Bonds (Measure M) | C17: av | D17: 0.0040% of AV | E17: 4e-05 | F17: =IF(C17="sqft",E17*Summary!$B$6,E17*Summary!$B$7) -> 50 | G17: — | I17: =IF(H17="","",IF(C17="sqft",H17*Summary!$B$6,H17*Summary!$B$7)) | J17: =IF(H17="","",(E17-H17)/H17) | K17: ADOPTED — MATCHES estimate ✓ | L17: Ad valorem; debt-service driven | M17: Ord 8,026: 0.0040% AV
B20: Per-sq-ft parcel taxes (sum) | F20: =SUMIF(C5:C17,"sqft",F5:F17) -> 2001.006
B21: Ad valorem bond levies (sum) | F21: =SUMIF(C5:C17,"av",F5:F17) -> 612.5
B22: COMBINED ANNUAL | F22: =F20+F21 -> 2613.506
B23: Note: UNVERIFIED items still included in totals using Geoff's published rate.

Sheet Full Parcel Burden
A1: Berkeley Parcel — Total Property-Tax Burden (All Jurisdictions)
A2: Model parcel: 1,800 sq ft dwelling, assessed value $1,250,000. City of Berkeley = FY2027 ADOPTED rates (Ord. 6/30/26). BUSD & county/regional = 2025-26 (latest billed) — those bodies set FY2027 rates later in summer. Prepared 2026-06-22 by BeTH.
A3: Combines THREE separate taxing entities (City, school district, county/regional). Shown with subtotals so jurisdictions are not conflated. Ad valorem lines scale with assessed value; per-sq-ft lines scale with building size; fixed charges do not scale.
A5: Assumptions
A6: Dwelling size (sq ft) | C6: 1800
A7: Assessed value ($) | C7: 1250000
A9: Measure / Levy | B9: Basis | C9: Rate | D9: Rate (num) | E9: Annual $ | F9: Confidence | G9: Source / Notes
A10: CITY OF BERKELEY
A11: Library Relief Act 2024 (Measure X) | B11: sqft | C11: 6.297¢/sf | D11: 0.06297 | E11: =D11*$C$6 -> 113.346 | F11: High | G11: Ord 8,013 (adopted 6/30/26)
A12: Library Services Tax (1980 Act) | B12: sqft | C12: 31.28¢/sf | D12: 0.3128 | E12: =D12*$C$6 -> 563.04 | F12: High | G12: Ord 8,014
A13: Emergency Svcs Disabled (Measure E) | B13: sqft | C13: 2.339¢/sf | D13: 0.02339 | E13: =D13*$C$6 -> 42.102 | F13: High | G13: Ord 8,018
A14: Fire Protection & Emerg Prep (Measure GG) | B14: sqft | C14: 7.026¢/sf | D14: 0.07026 | E14: =D14*$C$6 -> 126.468 | F14: High | G14: Ord 8,019 (dwelling rate)
A15: Firefighting/EMS/Wildfire (Measure FF 2020) | B15: sqft | C15: 13.633¢/sf | D15: 0.13633 | E15: =D15*$C$6 -> 245.394 | F15: High | G15: Ord 8,020
A16: Emergency Medical Svcs (Paramedic Tax) | B16: sqft | C16: 4.92¢/sf | D16: 0.0492 | E16: =D16*$C$6 -> 88.56 | F16: High | G16: Ord 8,021
A17: Parks, Trees & Landscaping (Measures F & Y) | B17: sqft | C17: 27.83¢/sf | D17: 0.2783 | E17: =D17*$C$6 -> 500.94 | F17: High | G17: Ord 8,023
A18: Safe Streets Tax (Measure FF 2024) | B18: sqft | C18: 17.842¢/sf | D18: 0.17842 | E18: =D18*$C$6 -> 321.156 | F18: High | G18: Ord 8,025 (dwelling rate)
A19: 2015 Refunding GO Bonds (Measures G/S/I) | B19: av | C19: 0.0075% | D19: 7.5e-05 | E19: =D19*$C$7 -> 93.75 | F19: High | G19: Ord 8,016
A20: Affordable Housing Bonds (Measure O) | B20: av | C20: 0.0200% | D20: 0.0002 | E20: =D20*$C$7 -> 250 | F20: High | G20: Ord 8,017
A21: Infrastructure & Facilities Bonds (Measure T1) | B21: av | C21: 0.0140% | D21: 0.00014 | E21: =D21*$C$7 -> 175 | F21: High | G21: Ord 8,022
A22: Branch Library Bonds (2008 Measure FF) | B22: av | C22: 0.0035% | D22: 3.5e-05 | E22: =D22*$C$7 -> 43.75 | F22: High | G22: Ord 8,024
A23: Street & Watershed Bonds (Measure M) | B23: av | C23: 0.0040% | D23: 4e-05 | E23: =D23*$C$7 -> 50 | F23: High | G23: Ord 8,026
A24: City fixed direct charges (storm water, street lighting, paramedic CSA, etc.) | B24: flat | C24: — | D24: 161.32 | E24: =D24 -> 161.32 | F24: High | G24: 2025-26 secured bill (flat, non-scaling)
A25: City of Berkeley — subtotal | E25: =SUM(E11:E24) -> 2774.826
A26: BERKELEY UNIFIED SCHOOL DISTRICT (BUSD)
A27: BSEP / School Ed Programs (Measure H 2024) | B27: sqft | C27: $0.54/sf | D27: 0.54 | E27: =D27*$C$6 -> 972 | F27: High | G27: Alameda Co. Treasurer 2025-26; per-sf confirmed
A28: Educator Recruit/Retain – BERRA (Measure E 2020) | B28: sqft | C28: 14.51¢/sf | D28: 0.1451 | E28: =D28*$C$6 -> 261.18 | F28: Moderate | G28: Derived from 2025-26 bill; confirm vs district resolution
A29: School Safety & Maintenance (Measure H 2020) | B29: sqft | C29: 10.65¢/sf | D29: 0.1065 | E29: =D29*$C$6 -> 191.7 | F29: Moderate | G29: Derived from 2025-26 bill; confirm vs district resolution
A30: BUSD GO Bonds (Measures I 2010 + G 2020) | B30: av | C30: 0.1154% | D30: 0.001154 | E30: =D30*$C$7 -> 1442.5 | F30: High | G30: Alameda Co. Auditor Tax Rate Book, TRA 13-000, 2025-26
A31: BUSD — subtotal | E31: =SUM(E27:E30) -> 2867.38
A32: ALAMEDA COUNTY & REGIONAL DISTRICTS
A33: Base 1% General Levy (Prop 13) | B33: av | C33: 1.0000% | D33: 0.01 | E33: =D33*$C$7 -> 12500 | F33: High | G33: Alameda Co. Auditor, TRA 13-000
A34: Alameda County GO Bond | B34: av | C34: 0.0084% | D34: 8.4e-05 | E34: =D34*$C$7 -> 105 | F34: High | G34: Auditor Tax Rate Book 2025-26
A35: Peralta Community College Bonds | B35: av | C35: 0.0432% | D35: 0.000432 | E35: =D35*$C$7 -> 540 | F35: High | G35: Auditor Tax Rate Book 2025-26
A36: BART GO Bonds | B36: av | C36: 0.0152% | D36: 0.000152 | E36: =D36*$C$7 -> 190 | F36: High | G36: Auditor Tax Rate Book 2025-26
A37: East Bay Regional Park District (EBRPD) | B37: av | C37: 0.0011% | D37: 1.1e-05 | E37: =D37*$C$7 -> 13.75 | F37: High | G37: Auditor Tax Rate Book 2025-26
A38: Regional fixed charges (EBMUD, AC Transit VV, Peralta parcel, mosquito/vector, EBRPD CFD, etc.) | B38: flat | C38: — | D38: 358.26 | E38: =D38 -> 358.26 | F38: High | G38: 2025-26 secured bill (flat, non-scaling)
A39: County & regional — subtotal | E39: =SUM(E33:E38) -> 13707.01
A40: TOTAL ANNUAL PROPERTY-TAX BURDEN (this parcel) | E40: =E25+E31+E39 -> 19349.216
A42: RECONCILIATION: The ad valorem lines (City bonds 0.0490% + BUSD bonds 0.1154% + base 1% + county 0.0084% + Peralta 0.0432% + BART 0.0152% + EBRPD 0.0011%) sum to exactly 1.2323% — the Alameda County Auditor composite rate for Berkeley TRA 13-000. Total burden cross-checks against a real 2025-26 Berkeley bill (~$19.4k at similar AV).
A43: NOT THE CITY BUDGET. This is the tax bill on ONE parcel across all overlapping jurisdictions — not the City of Berkeley's spending. Only the City subtotal is money the City government levies.
...
